// @flow

import _test from 'lobot/test'
import Task from '../src'

const test = _test.wrap('chain')

test('works with of + of', 1, t => {
  Task.of(2).chain(x => Task.of(x + 10)).run(t.calledWith(12))
})

test('static alias works', 1, t => {
  Task.chain(x => Task.of(x + 10), Task.of(2)).run(t.calledWith(12))
})

test('works with of + rejected', 1, t => {
  Task.of(2).chain(x => Task.rejected(x + 10)).run({failure: t.calledWith(12)})
})

test('works with rejected + of', 1, t => {
  Task.rejected(2).chain(x => Task.of(x + 10)).run({failure: t.calledWith(2)})
})

test('cancelation - orig. task', 1, t => {
  Task.create(() => t.calledOnce()).chain(() => Task.of()).run({})()
})

test('cancelation - spawned task - orig. sync', 1, t => {
  Task.of().chain(() => Task.create(() => t.calledOnce())).run({})()
})

test('cancelation - spawned task - orig. async', 1, t => {
  let s: any = null
  const orig = Task.create(_s => {s = _s})
  const spawned = Task.create(() => t.calledOnce())
  const cancel = orig.chain(() => spawned).run({})
  s()
  cancel()
})

test('exception thrown from fn (no catch cb)', 1, t => {
  t.throws(() => {
    Task.of().chain(() => { throw new Error('err1') }).run({})
  }, /err1/)
})

test('exception thrown from fn (with catch cb)', 1, t => {
  Task.of().chain(() => { throw 2 }).run({catch: t.calledWith(2)})
})

const thrower1 = Task.create(() => { throw new Error('err1') })
const thrower2 = Task.create(() => { throw 2 })

test('exception thrown from parent task (no catch cb)', 1, t => {
  t.throws(() => {
    thrower1.chain(() => Task.of()).run({})
  }, /err1/)
})

test('exception thrown from parent task (with catch cb)', 1, t => {
  thrower2.chain(() => Task.of()).run({catch: t.calledWith(2)})
})

test('exception thrown from child task (no catch cb)', 1, t => {
  t.throws(() => {
    Task.of().chain(() => thrower1).run({})
  }, /err1/)
})

test('exception thrown from child task (with catch cb)', 1, t => {
  Task.of().chain(() => thrower2).run({catch: t.calledWith(2)})
})

test('exception thrown from child task (with catch cb, async)', 1, t => {
  let s = (null: any)
  let thrower = Task.create(_s => { s = _s }).chain(() => { throw 2 })
  Task.of().chain(() => thrower).run({catch: t.calledWith(2)})
  s()
})

test('exception thrown from child task (no catch cb, async)', 1, t => {
  let s = (null: any)
  let thrower = Task.create(_s => { s = _s }).chain(() => { throw new Error('err1') })
  Task.of().chain(() => thrower).run({})
  t.throws(s, /err1/)
})

test('this==undefined in success cd', 1, t => {
  Task.of(2).chain(x => Task.of(x)).run({success() { t.equal(this, undefined) }})
})

test('this==undefined in failure cd', 1, t => {
  Task.rejected(2).chain(x => Task.of(x)).run({failure() { t.equal(this, undefined) }})
})

test('this==undefined in fn', 1, t => {
  Task.of(2).chain(function(x) { t.equal(this, undefined); return Task.of(x) }).run({})
})


// Flow

Task.of(2).chain(x => x > 10 ? Task.of('') : Task.rejected(true)).run({
  success(x) {
    (x: string)
  },
  failure(x) {
    (x: boolean)
  },
})
