// @flow

import _test from 'lobot/test'
import Task from '../src'

const test = _test.wrap('orElse')

test('works with of + of', 1, t => {
  Task.of(2).orElse(x => Task.of(x + 10)).run(t.calledWith(2))
})

test('static alias works', 1, t => {
  Task.orElse(x => Task.of(x + 10), Task.of(2)).run(t.calledWith(2))
})

test('works with of + rejected', 1, t => {
  Task.of(2).orElse(x => Task.rejected(x + 10)).run(t.calledWith(2))
})

test('works with rejected + of', 1, t => {
  Task.rejected(2).orElse(x => Task.of(x + 10)).run(t.calledWith(12))
})

test('works with rejected + rejected', 1, t => {
  Task.rejected(2).orElse(x => Task.rejected(x + 10)).run({failure: t.calledWith(12)})
})

test('cancelation - orig. task', 1, t => {
  Task.create(() => t.calledOnce()).orElse(() => Task.of()).run({})()
})

test('cancelation - spawned task - orig. sync', 1, t => {
  Task.rejected().orElse(() => Task.create(() => t.calledOnce())).run({})()
})

test('cancelation - spawned task - orig. async', 1, t => {
  let s: any = null
  const orig = Task.create((_, _s) => {s = _s})
  const spawned = Task.create(() => t.calledOnce())
  const cancel = orig.orElse(() => spawned).run({})
  s()
  cancel()
})

test('exception thrown from fn (no catch cb)', 1, t => {
  t.throws(() => {
    Task.rejected().orElse(() => { throw new Error('err1') }).run({})
  }, /err1/)
})

test('exception thrown from fn (with catch cb)', 1, t => {
  Task.rejected().orElse(() => { throw 2 }).run({catch: t.calledWith(2)})
})

const thrower1 = Task.create(() => { throw new Error('err1') })
const thrower2 = Task.create(() => { throw 2 })

test('exception thrown from parent task (no catch cb)', 1, t => {
  t.throws(() => {
    thrower1.orElse(() => Task.of()).run({})
  }, /err1/)
})

test('exception thrown from parent task (with catch cb)', 1, t => {
  thrower2.orElse(() => Task.of()).run({catch: t.calledWith(2)})
})

test('exception thrown from child task (no catch cb)', 1, t => {
  t.throws(() => {
    Task.rejected().orElse(() => thrower1).run({})
  }, /err1/)
})

test('exception thrown from child task (with catch cb)', 1, t => {
  Task.rejected().orElse(() => thrower2).run({catch: t.calledWith(2)})
})

test('exception thrown from child task (with catch cb, async)', 1, t => {
  let f = (null: any)
  let thrower = Task.create((_, _f) => { f = _f }).orElse(() => { throw 2 })
  Task.of().chain(() => thrower).run({catch: t.calledWith(2)})
  f()
})

test('exception thrown from child task (no catch cb, async)', 1, t => {
  let f = (null: any)
  let thrower = Task.create((_, _f) => { f = _f }).orElse(() => { throw new Error('err1') })
  Task.of().chain(() => thrower).run({})
  t.throws(f, /err1/)
})

test('this==undefined in success cd', 1, t => {
  Task.of(2).chain(x => Task.of(x)).run({success() { t.equal(this, undefined) }})
})

test('this==undefined in success cd', 1, t => {
  Task.of(2).orElse(x => Task.rejected(x)).run({success() { t.equal(this, undefined) }})
})

test('this==undefined in failure cd', 1, t => {
  Task.rejected(2).orElse(x => Task.rejected(x)).run({failure() { t.equal(this, undefined) }})
})

test('this==undefined in fn', 1, t => {
  Task.rejected(2).orElse(function(x) { t.equal(this, undefined); return Task.of(x) }).run({})
})
